2024-03-26 02:46:16 INFO     App started
2024-03-26 02:46:43 INFO     Authenticating user...
2024-03-26 02:46:45 ERROR    b''
2024-03-26 02:46:46 ERROR    An error occurred
NoneType: None
2024-03-26 02:51:46 INFO     App started
2024-03-26 02:52:47 ERROR    Exception on /createuser [POST]
Traceback (most recent call last):
  File "c:\Users\kskar\anaconda3\envs\housingproj\lib\site-packages\sqlalchemy\engine\base.py", line 1970, in _exec_single_context
    self.dialect.do_execute(
  File "c:\Users\kskar\anaconda3\envs\housingproj\lib\site-packages\sqlalchemy\engine\default.py", line 924, in do_execute
    cursor.execute(statement, parameters)
  File "c:\Users\kskar\anaconda3\envs\housingproj\lib\site-packages\MySQLdb\cursors.py", line 179, in execute
    res = self._query(mogrified_query)
  File "c:\Users\kskar\anaconda3\envs\housingproj\lib\site-packages\MySQLdb\cursors.py", line 330, in _query
    db.query(q)
  File "c:\Users\kskar\anaconda3\envs\housingproj\lib\site-packages\MySQLdb\connections.py", line 261, in query
    _mysql.connection.query(self, query)
MySQLdb.IntegrityError: (1452, 'Cannot add or update a child row: a foreign key constraint fails (`campusaccomodation`.`users`, CONSTRAINT `users_ibfk_1` FOREIGN KEY (`id`) REFERENCES `student` (`studentid`))')

The above exception was the direct cause of the following exception:

Traceback (most recent call last):
  File "c:\Users\kskar\anaconda3\envs\housingproj\lib\site-packages\flask\app.py", line 1463, in wsgi_app
    response = self.full_dispatch_request()
  File "c:\Users\kskar\anaconda3\envs\housingproj\lib\site-packages\flask\app.py", line 872, in full_dispatch_request
    rv = self.handle_user_exception(e)
  File "c:\Users\kskar\anaconda3\envs\housingproj\lib\site-packages\flask_cors\extension.py", line 176, in wrapped_function
    return cors_after_request(app.make_response(f(*args, **kwargs)))
  File "c:\Users\kskar\anaconda3\envs\housingproj\lib\site-packages\flask\app.py", line 870, in full_dispatch_request
    rv = self.dispatch_request()
  File "c:\Users\kskar\anaconda3\envs\housingproj\lib\site-packages\flask\app.py", line 855, in dispatch_request
    return self.ensure_sync(self.view_functions[rule.endpoint])(**view_args)  # type: ignore[no-any-return]
  File "c:\Users\kskar\anaconda3\envs\housingproj\lib\site-packages\flask_cors\decorator.py", line 130, in wrapped_function
    resp = make_response(f(*args, **kwargs))
  File "d:\SFBU\Syllabus\Data Modeling and Implementation Techniques\housingproject\Controller\user_route.py", line 28, in CreateUser
    user_service.user_registration(username,1,password)
  File "d:\SFBU\Syllabus\Data Modeling and Implementation Techniques\housingproject\Service\usersService.py", line 12, in user_registration
    self.user_repository.register_user(userid, usertype, password)
  File "d:\SFBU\Syllabus\Data Modeling and Implementation Techniques\housingproject\Repository\userRepository.py", line 40, in register_user
    db.session.commit()
  File "c:\Users\kskar\anaconda3\envs\housingproj\lib\site-packages\sqlalchemy\orm\scoping.py", line 597, in commit
    return self._proxied.commit()
  File "c:\Users\kskar\anaconda3\envs\housingproj\lib\site-packages\sqlalchemy\orm\session.py", line 1972, in commit
    trans.commit(_to_root=True)
  File "<string>", line 2, in commit
  File "c:\Users\kskar\anaconda3\envs\housingproj\lib\site-packages\sqlalchemy\orm\state_changes.py", line 139, in _go
    ret_value = fn(self, *arg, **kw)
  File "c:\Users\kskar\anaconda3\envs\housingproj\lib\site-packages\sqlalchemy\orm\session.py", line 1257, in commit
    self._prepare_impl()
  File "<string>", line 2, in _prepare_impl
  File "c:\Users\kskar\anaconda3\envs\housingproj\lib\site-packages\sqlalchemy\orm\state_changes.py", line 139, in _go
    ret_value = fn(self, *arg, **kw)
  File "c:\Users\kskar\anaconda3\envs\housingproj\lib\site-packages\sqlalchemy\orm\session.py", line 1232, in _prepare_impl
    self.session.flush()
  File "c:\Users\kskar\anaconda3\envs\housingproj\lib\site-packages\sqlalchemy\orm\session.py", line 4296, in flush
    self._flush(objects)
  File "c:\Users\kskar\anaconda3\envs\housingproj\lib\site-packages\sqlalchemy\orm\session.py", line 4431, in _flush
    with util.safe_reraise():
  File "c:\Users\kskar\anaconda3\envs\housingproj\lib\site-packages\sqlalchemy\util\langhelpers.py", line 146, in __exit__
    raise exc_value.with_traceback(exc_tb)
  File "c:\Users\kskar\anaconda3\envs\housingproj\lib\site-packages\sqlalchemy\orm\session.py", line 4392, in _flush
    flush_context.execute()
  File "c:\Users\kskar\anaconda3\envs\housingproj\lib\site-packages\sqlalchemy\orm\unitofwork.py", line 466, in execute
    rec.execute(self)
  File "c:\Users\kskar\anaconda3\envs\housingproj\lib\site-packages\sqlalchemy\orm\unitofwork.py", line 642, in execute
    util.preloaded.orm_persistence.save_obj(
  File "c:\Users\kskar\anaconda3\envs\housingproj\lib\site-packages\sqlalchemy\orm\persistence.py", line 93, in save_obj
    _emit_insert_statements(
  File "c:\Users\kskar\anaconda3\envs\housingproj\lib\site-packages\sqlalchemy\orm\persistence.py", line 1048, in _emit_insert_statements
    result = connection.execute(
  File "c:\Users\kskar\anaconda3\envs\housingproj\lib\site-packages\sqlalchemy\engine\base.py", line 1421, in execute
    return meth(
  File "c:\Users\kskar\anaconda3\envs\housingproj\lib\site-packages\sqlalchemy\sql\elements.py", line 514, in _execute_on_connection
    return connection._execute_clauseelement(
  File "c:\Users\kskar\anaconda3\envs\housingproj\lib\site-packages\sqlalchemy\engine\base.py", line 1643, in _execute_clauseelement
    ret = self._execute_context(
  File "c:\Users\kskar\anaconda3\envs\housingproj\lib\site-packages\sqlalchemy\engine\base.py", line 1849, in _execute_context
    return self._exec_single_context(
  File "c:\Users\kskar\anaconda3\envs\housingproj\lib\site-packages\sqlalchemy\engine\base.py", line 1989, in _exec_single_context
    self._handle_dbapi_exception(
  File "c:\Users\kskar\anaconda3\envs\housingproj\lib\site-packages\sqlalchemy\engine\base.py", line 2356, in _handle_dbapi_exception
    raise sqlalchemy_exception.with_traceback(exc_info[2]) from e
  File "c:\Users\kskar\anaconda3\envs\housingproj\lib\site-packages\sqlalchemy\engine\base.py", line 1970, in _exec_single_context
    self.dialect.do_execute(
  File "c:\Users\kskar\anaconda3\envs\housingproj\lib\site-packages\sqlalchemy\engine\default.py", line 924, in do_execute
    cursor.execute(statement, parameters)
  File "c:\Users\kskar\anaconda3\envs\housingproj\lib\site-packages\MySQLdb\cursors.py", line 179, in execute
    res = self._query(mogrified_query)
  File "c:\Users\kskar\anaconda3\envs\housingproj\lib\site-packages\MySQLdb\cursors.py", line 330, in _query
    db.query(q)
  File "c:\Users\kskar\anaconda3\envs\housingproj\lib\site-packages\MySQLdb\connections.py", line 261, in query
    _mysql.connection.query(self, query)
sqlalchemy.exc.IntegrityError: (MySQLdb.IntegrityError) (1452, 'Cannot add or update a child row: a foreign key constraint fails (`campusaccomodation`.`users`, CONSTRAINT `users_ibfk_1` FOREIGN KEY (`id`) REFERENCES `student` (`studentid`))')
[SQL: INSERT INTO `Users` (id, usertypeid, password) VALUES (%s, %s, %s)]
[parameters: ('20087', 1, b'$2b$12$w/ThZzlTtVb2llgI8w6Bl.qmVG/tLaO4NGDpdCW8pqAgEYyVHRNh2')]
(Background on this error at: https://sqlalche.me/e/20/gkpj)
2024-03-26 03:04:51 INFO     App started
2024-03-26 03:05:14 INFO     Authenticating user...
2024-03-26 03:05:14 ERROR    b''
2024-03-26 03:05:16 ERROR    An error occurred
NoneType: None
2024-03-26 03:06:21 INFO     (MySQLdb.IntegrityError) (1452, 'Cannot add or update a child row: a foreign key constraint fails (`campusaccomodation`.`users`, CONSTRAINT `users_ibfk_1` FOREIGN KEY (`id`) REFERENCES `student` (`studentid`))')
[SQL: INSERT INTO `Users` (id, usertypeid, password) VALUES (%s, %s, %s)]
[parameters: ('20087', 1, b'$2b$12$k5nY1OUEL0JODlOezvzbD.MSm9mgwQZsH2ft5bvo9XQS7AGgpWkUy')]
(Background on this error at: https://sqlalche.me/e/20/gkpj)
2024-03-26 03:08:28 INFO     App started
2024-03-26 03:10:17 INFO     Authenticating user...
2024-03-26 03:10:18 ERROR    b''
2024-03-26 03:10:19 ERROR    An error occurred
NoneType: None
2024-03-26 03:11:02 ERROR    Exception on /halllist [GET]
Traceback (most recent call last):
  File "c:\Users\kskar\anaconda3\envs\housingproj\lib\site-packages\flask\app.py", line 1463, in wsgi_app
    response = self.full_dispatch_request()
  File "c:\Users\kskar\anaconda3\envs\housingproj\lib\site-packages\flask\app.py", line 872, in full_dispatch_request
    rv = self.handle_user_exception(e)
  File "c:\Users\kskar\anaconda3\envs\housingproj\lib\site-packages\flask_cors\extension.py", line 176, in wrapped_function
    return cors_after_request(app.make_response(f(*args, **kwargs)))
  File "c:\Users\kskar\anaconda3\envs\housingproj\lib\site-packages\flask\app.py", line 870, in full_dispatch_request
    rv = self.dispatch_request()
  File "c:\Users\kskar\anaconda3\envs\housingproj\lib\site-packages\flask\app.py", line 855, in dispatch_request
    return self.ensure_sync(self.view_functions[rule.endpoint])(**view_args)  # type: ignore[no-any-return]
  File "c:\Users\kskar\anaconda3\envs\housingproj\lib\site-packages\flask_cors\decorator.py", line 130, in wrapped_function
    resp = make_response(f(*args, **kwargs))
  File "c:\Users\kskar\anaconda3\envs\housingproj\lib\site-packages\flask_login\utils.py", line 290, in decorated_view
    return current_app.ensure_sync(func)(*args, **kwargs)
  File "d:\SFBU\Syllabus\Data Modeling and Implementation Techniques\housingproject\Controller\hallofresidence_route.py", line 35, in OngetHallResidenceList
    response = jsonify(halllist)
  File "c:\Users\kskar\anaconda3\envs\housingproj\lib\site-packages\flask\json\__init__.py", line 170, in jsonify
    return current_app.json.response(*args, **kwargs)  # type: ignore[return-value]
  File "c:\Users\kskar\anaconda3\envs\housingproj\lib\site-packages\flask\json\provider.py", line 214, in response
    f"{self.dumps(obj, **dump_args)}\n", mimetype=self.mimetype
  File "c:\Users\kskar\anaconda3\envs\housingproj\lib\site-packages\flask\json\provider.py", line 179, in dumps
    return json.dumps(obj, **kwargs)
  File "c:\Users\kskar\anaconda3\envs\housingproj\lib\json\__init__.py", line 238, in dumps
    **kw).encode(obj)
  File "c:\Users\kskar\anaconda3\envs\housingproj\lib\json\encoder.py", line 199, in encode
    chunks = self.iterencode(o, _one_shot=True)
  File "c:\Users\kskar\anaconda3\envs\housingproj\lib\json\encoder.py", line 257, in iterencode
    return _iterencode(o, 0)
  File "c:\Users\kskar\anaconda3\envs\housingproj\lib\site-packages\flask\json\provider.py", line 121, in _default
    raise TypeError(f"Object of type {type(o).__name__} is not JSON serializable")
TypeError: Object of type HallOfResidence is not JSON serializable
2024-03-26 03:37:11 INFO     App started
2024-03-26 03:37:36 INFO     Authenticating user...
2024-03-26 03:37:36 ERROR    b''
2024-03-26 03:37:37 ERROR    An error occurred
NoneType: None
2024-03-26 03:37:55 ERROR    Exception on /halllist [GET]
Traceback (most recent call last):
  File "c:\Users\kskar\anaconda3\envs\housingproj\lib\site-packages\flask\app.py", line 1463, in wsgi_app
    response = self.full_dispatch_request()
  File "c:\Users\kskar\anaconda3\envs\housingproj\lib\site-packages\flask\app.py", line 872, in full_dispatch_request
    rv = self.handle_user_exception(e)
  File "c:\Users\kskar\anaconda3\envs\housingproj\lib\site-packages\flask_cors\extension.py", line 176, in wrapped_function
    return cors_after_request(app.make_response(f(*args, **kwargs)))
  File "c:\Users\kskar\anaconda3\envs\housingproj\lib\site-packages\flask\app.py", line 870, in full_dispatch_request
    rv = self.dispatch_request()
  File "c:\Users\kskar\anaconda3\envs\housingproj\lib\site-packages\flask\app.py", line 855, in dispatch_request
    return self.ensure_sync(self.view_functions[rule.endpoint])(**view_args)  # type: ignore[no-any-return]
  File "c:\Users\kskar\anaconda3\envs\housingproj\lib\site-packages\flask_cors\decorator.py", line 130, in wrapped_function
    resp = make_response(f(*args, **kwargs))
  File "c:\Users\kskar\anaconda3\envs\housingproj\lib\site-packages\flask_login\utils.py", line 290, in decorated_view
    return current_app.ensure_sync(func)(*args, **kwargs)
  File "d:\SFBU\Syllabus\Data Modeling and Implementation Techniques\housingproject\Controller\hallofresidence_route.py", line 34, in OngetHallResidenceList
    halllist = hallResidenceService.get_all_hallList()
  File "d:\SFBU\Syllabus\Data Modeling and Implementation Techniques\housingproject\Service\hallofresidenceService.py", line 10, in get_all_hallList
    halllist = [HallOfResidenceSerializer().load(data) for data in halllistdata]
  File "d:\SFBU\Syllabus\Data Modeling and Implementation Techniques\housingproject\Service\hallofresidenceService.py", line 10, in <listcomp>
    halllist = [HallOfResidenceSerializer().load(data) for data in halllistdata]
  File "c:\Users\kskar\anaconda3\envs\housingproj\lib\site-packages\marshmallow_sqlalchemy\load_instance_mixin.py", line 100, in load
    return super().load(data, **kwargs)
  File "c:\Users\kskar\anaconda3\envs\housingproj\lib\site-packages\marshmallow\schema.py", line 722, in load
    return self._do_load(
  File "c:\Users\kskar\anaconda3\envs\housingproj\lib\site-packages\marshmallow\schema.py", line 909, in _do_load
    raise exc
marshmallow.exceptions.ValidationError: {'_schema': ['Invalid input type.']}
2024-03-26 03:44:04 INFO     App started
2024-03-26 03:44:25 INFO     Authenticating user...
2024-03-26 03:44:25 ERROR    b''
2024-03-26 03:44:25 ERROR    An error occurred
NoneType: None
2024-03-26 04:02:40 INFO     App started
2024-03-26 04:04:07 INFO     App started
2024-03-26 04:49:05 INFO     App started
2024-03-26 04:50:07 INFO     App started
2024-03-26 04:59:29 INFO     App started
2024-03-26 05:06:08 INFO     App started
2024-03-26 05:06:16 INFO     App started
2024-03-26 05:07:43 INFO     App started
2024-03-26 05:10:51 INFO     App started
2024-03-26 05:12:14 INFO     App started
2024-03-26 05:13:42 INFO     App started
2024-03-26 05:46:31 INFO     App started
2024-03-26 05:46:48 ERROR    Exception on /halldetail/0 [GET]
Traceback (most recent call last):
  File "c:\Users\kskar\anaconda3\envs\housingproj\lib\site-packages\flask\app.py", line 1463, in wsgi_app
    response = self.full_dispatch_request()
  File "c:\Users\kskar\anaconda3\envs\housingproj\lib\site-packages\flask\app.py", line 872, in full_dispatch_request
    rv = self.handle_user_exception(e)
  File "c:\Users\kskar\anaconda3\envs\housingproj\lib\site-packages\flask_cors\extension.py", line 176, in wrapped_function
    return cors_after_request(app.make_response(f(*args, **kwargs)))
  File "c:\Users\kskar\anaconda3\envs\housingproj\lib\site-packages\flask\app.py", line 870, in full_dispatch_request
    rv = self.dispatch_request()
  File "c:\Users\kskar\anaconda3\envs\housingproj\lib\site-packages\flask\app.py", line 855, in dispatch_request
    return self.ensure_sync(self.view_functions[rule.endpoint])(**view_args)  # type: ignore[no-any-return]
  File "c:\Users\kskar\anaconda3\envs\housingproj\lib\site-packages\flask_cors\decorator.py", line 130, in wrapped_function
    resp = make_response(f(*args, **kwargs))
  File "c:\Users\kskar\anaconda3\envs\housingproj\lib\site-packages\flask_login\utils.py", line 290, in decorated_view
    return current_app.ensure_sync(func)(*args, **kwargs)
TypeError: HallDetailPage() got an unexpected keyword argument 'hall_id'
2024-03-26 05:47:22 INFO     Authenticating user...
2024-03-26 05:47:22 ERROR    b''
2024-03-26 05:47:23 ERROR    An error occurred
NoneType: None
2024-03-26 05:52:44 ERROR    Exception on /halldetail/0 [GET]
Traceback (most recent call last):
  File "c:\Users\kskar\anaconda3\envs\housingproj\lib\site-packages\flask\app.py", line 1463, in wsgi_app
    response = self.full_dispatch_request()
  File "c:\Users\kskar\anaconda3\envs\housingproj\lib\site-packages\flask\app.py", line 872, in full_dispatch_request
    rv = self.handle_user_exception(e)
  File "c:\Users\kskar\anaconda3\envs\housingproj\lib\site-packages\flask_cors\extension.py", line 176, in wrapped_function
    return cors_after_request(app.make_response(f(*args, **kwargs)))
  File "c:\Users\kskar\anaconda3\envs\housingproj\lib\site-packages\flask\app.py", line 870, in full_dispatch_request
    rv = self.dispatch_request()
  File "c:\Users\kskar\anaconda3\envs\housingproj\lib\site-packages\flask\app.py", line 855, in dispatch_request
    return self.ensure_sync(self.view_functions[rule.endpoint])(**view_args)  # type: ignore[no-any-return]
  File "c:\Users\kskar\anaconda3\envs\housingproj\lib\site-packages\flask_cors\decorator.py", line 130, in wrapped_function
    resp = make_response(f(*args, **kwargs))
  File "c:\Users\kskar\anaconda3\envs\housingproj\lib\site-packages\flask_login\utils.py", line 290, in decorated_view
    return current_app.ensure_sync(func)(*args, **kwargs)
TypeError: HallDetailPage() got an unexpected keyword argument 'hall_id'
2024-03-26 05:53:12 INFO     App started
2024-03-26 05:53:30 ERROR    Exception on /halldetail/0 [GET]
Traceback (most recent call last):
  File "c:\Users\kskar\anaconda3\envs\housingproj\lib\site-packages\flask\app.py", line 1463, in wsgi_app
    response = self.full_dispatch_request()
  File "c:\Users\kskar\anaconda3\envs\housingproj\lib\site-packages\flask\app.py", line 872, in full_dispatch_request
    rv = self.handle_user_exception(e)
  File "c:\Users\kskar\anaconda3\envs\housingproj\lib\site-packages\flask_cors\extension.py", line 176, in wrapped_function
    return cors_after_request(app.make_response(f(*args, **kwargs)))
  File "c:\Users\kskar\anaconda3\envs\housingproj\lib\site-packages\flask\app.py", line 870, in full_dispatch_request
    rv = self.dispatch_request()
  File "c:\Users\kskar\anaconda3\envs\housingproj\lib\site-packages\flask\app.py", line 855, in dispatch_request
    return self.ensure_sync(self.view_functions[rule.endpoint])(**view_args)  # type: ignore[no-any-return]
  File "c:\Users\kskar\anaconda3\envs\housingproj\lib\site-packages\flask_cors\decorator.py", line 130, in wrapped_function
    resp = make_response(f(*args, **kwargs))
  File "c:\Users\kskar\anaconda3\envs\housingproj\lib\site-packages\flask_login\utils.py", line 290, in decorated_view
    return current_app.ensure_sync(func)(*args, **kwargs)
TypeError: HallDetailPage() got an unexpected keyword argument 'hall_id'
2024-03-26 05:55:39 ERROR    Exception on /halldetail/0 [GET]
Traceback (most recent call last):
  File "c:\Users\kskar\anaconda3\envs\housingproj\lib\site-packages\flask\app.py", line 1463, in wsgi_app
    response = self.full_dispatch_request()
  File "c:\Users\kskar\anaconda3\envs\housingproj\lib\site-packages\flask\app.py", line 872, in full_dispatch_request
    rv = self.handle_user_exception(e)
  File "c:\Users\kskar\anaconda3\envs\housingproj\lib\site-packages\flask_cors\extension.py", line 176, in wrapped_function
    return cors_after_request(app.make_response(f(*args, **kwargs)))
  File "c:\Users\kskar\anaconda3\envs\housingproj\lib\site-packages\flask\app.py", line 870, in full_dispatch_request
    rv = self.dispatch_request()
  File "c:\Users\kskar\anaconda3\envs\housingproj\lib\site-packages\flask\app.py", line 855, in dispatch_request
    return self.ensure_sync(self.view_functions[rule.endpoint])(**view_args)  # type: ignore[no-any-return]
  File "c:\Users\kskar\anaconda3\envs\housingproj\lib\site-packages\flask_cors\decorator.py", line 130, in wrapped_function
    resp = make_response(f(*args, **kwargs))
  File "c:\Users\kskar\anaconda3\envs\housingproj\lib\site-packages\flask_login\utils.py", line 290, in decorated_view
    return current_app.ensure_sync(func)(*args, **kwargs)
TypeError: HallDetailPage() got an unexpected keyword argument 'hall_id'
2024-03-26 05:58:35 INFO     App started
2024-03-26 06:03:27 INFO     App started
2024-03-26 06:06:57 INFO     App started
2024-03-26 06:11:00 INFO     App started
2024-03-26 06:25:30 INFO     App started
2024-03-26 06:27:21 INFO     App started
2024-03-26 06:27:34 ERROR    Exception on /halldetail/3001 [GET]
Traceback (most recent call last):
  File "c:\Users\kskar\anaconda3\envs\housingproj\lib\site-packages\flask\app.py", line 1463, in wsgi_app
    response = self.full_dispatch_request()
  File "c:\Users\kskar\anaconda3\envs\housingproj\lib\site-packages\flask\app.py", line 872, in full_dispatch_request
    rv = self.handle_user_exception(e)
  File "c:\Users\kskar\anaconda3\envs\housingproj\lib\site-packages\flask_cors\extension.py", line 176, in wrapped_function
    return cors_after_request(app.make_response(f(*args, **kwargs)))
  File "c:\Users\kskar\anaconda3\envs\housingproj\lib\site-packages\flask\app.py", line 870, in full_dispatch_request
    rv = self.dispatch_request()
  File "c:\Users\kskar\anaconda3\envs\housingproj\lib\site-packages\flask\app.py", line 855, in dispatch_request
    return self.ensure_sync(self.view_functions[rule.endpoint])(**view_args)  # type: ignore[no-any-return]
  File "c:\Users\kskar\anaconda3\envs\housingproj\lib\site-packages\flask_cors\decorator.py", line 130, in wrapped_function
    resp = make_response(f(*args, **kwargs))
  File "c:\Users\kskar\anaconda3\envs\housingproj\lib\site-packages\flask_login\utils.py", line 290, in decorated_view
    return current_app.ensure_sync(func)(*args, **kwargs)
  File "d:\SFBU\Syllabus\Data Modeling and Implementation Techniques\housingproject\Controller\hallofresidence_route.py", line 30, in HallDetailPage
    response = jsonify(render_template("hallresidence/hallDetailPartial.html", data=hallDetail))
  File "c:\Users\kskar\anaconda3\envs\housingproj\lib\site-packages\flask\templating.py", line 149, in render_template
    template = app.jinja_env.get_or_select_template(template_name_or_list)
  File "c:\Users\kskar\anaconda3\envs\housingproj\lib\site-packages\jinja2\environment.py", line 1081, in get_or_select_template
    return self.get_template(template_name_or_list, parent, globals)
  File "c:\Users\kskar\anaconda3\envs\housingproj\lib\site-packages\jinja2\environment.py", line 1010, in get_template
    return self._load_template(name, globals)
  File "c:\Users\kskar\anaconda3\envs\housingproj\lib\site-packages\jinja2\environment.py", line 969, in _load_template
    template = self.loader.load(self, name, self.make_globals(globals))
  File "c:\Users\kskar\anaconda3\envs\housingproj\lib\site-packages\jinja2\loaders.py", line 137, in load
    code = environment.compile(source, name, filename)
  File "c:\Users\kskar\anaconda3\envs\housingproj\lib\site-packages\jinja2\environment.py", line 768, in compile
    self.handle_exception(source=source_hint)
  File "c:\Users\kskar\anaconda3\envs\housingproj\lib\site-packages\jinja2\environment.py", line 936, in handle_exception
    raise rewrite_traceback_stack(source=source)
  File "d:\SFBU\Syllabus\Data Modeling and Implementation Techniques\housingproject\templates\hallresidence\hallDetailPartial.html", line 51, in template
    {{ manager.[name] }}
jinja2.exceptions.TemplateSyntaxError: expected name or number
2024-03-26 06:31:41 INFO     App started
2024-03-26 06:32:54 INFO     App started
2024-03-26 07:11:06 INFO     App started
2024-03-26 07:11:34 INFO     App started
2024-03-26 07:12:48 INFO     App started
